2025-02-02 23:10:16,904 - root - INFO - Бот успешно запущен!
2025-02-02 23:10:17,466 - root - ERROR - Критическая ошибка при запуске бота: cannot import name 'get_user_context' from 'app.shared' (C:\Users\Глеб\Desktop\kas\app\shared.py)
2025-02-02 23:10:17,469 - root - ERROR - Неизвестная ошибка: cannot import name 'application' from 'app.main' (C:\Users\Глеб\Desktop\kas\app\main.py)
2025-02-02 23:10:17,470 - root - INFO - Завершение работы бота...
2025-02-02 23:29:30,591 - root - INFO - Бот успешно запущен!
2025-02-02 23:29:32,273 - telegram.ext.Application - INFO - Application started
2025-02-02 23:30:21,360 - telegram.ext.Application - ERROR - No error handlers are registered, logging exception.
Traceback (most recent call last):
  File "C:\Users\Глеб\AppData\Local\Programs\Python\Python313\Lib\site-packages\telegram\ext\_application.py", line 1325, in process_update
    await coroutine
  File "C:\Users\Глеб\AppData\Local\Programs\Python\Python313\Lib\site-packages\telegram\ext\_handlers\basehandler.py", line 158, in handle_update
    return await self.callback(update, context)
           ^^^^^^^^^^^^^^^^^^^^^^^^^^^^^^^^^^^^
  File "C:\Users\Глеб\Desktop\kas\app\handlers.py", line 30, in start
    get_user_context(user_id)  # Создаем контекст пользователя
    ~~~~~~~~~~~~~~~~^^^^^^^^^
  File "C:\Users\Глеб\Desktop\kas\app\handlers.py", line 24, in get_user_context
    user_contexts[user_id] = UserContext(user_id, session)
                             ~~~~~~~~~~~^^^^^^^^^^^^^^^^^^
  File "C:\Users\Глеб\Desktop\kas\app\shared.py", line 44, in __init__
    self.bot_params = self.load_user_params()
                      ~~~~~~~~~~~~~~~~~~~~~^^
  File "C:\Users\Глеб\Desktop\kas\app\shared.py", line 52, in load_user_params
    user = self.db_session.query(User).filter_by(id=self.user_id).first()
  File "C:\Users\Глеб\AppData\Local\Programs\Python\Python313\Lib\site-packages\sqlalchemy\orm\query.py", line 2754, in first
    return self.limit(1)._iter().first()  # type: ignore
           ~~~~~~~~~~~~~~~~~~~^^
  File "C:\Users\Глеб\AppData\Local\Programs\Python\Python313\Lib\site-packages\sqlalchemy\orm\query.py", line 2853, in _iter
    result: Union[ScalarResult[_T], Result[_T]] = self.session.execute(
                                                  ~~~~~~~~~~~~~~~~~~~~^
        statement,
        ^^^^^^^^^^
        params,
        ^^^^^^^
        execution_options={"_sa_orm_load_options": self.load_options},
        ^^^^^^^^^^^^^^^^^^^^^^^^^^^^^^^^^^^^^^^^^^^^^^^^^^^^^^^^^^^^^^
    )
    ^
  File "C:\Users\Глеб\AppData\Local\Programs\Python\Python313\Lib\site-packages\sqlalchemy\orm\session.py", line 2365, in execute
    return self._execute_internal(
           ~~~~~~~~~~~~~~~~~~~~~~^
        statement,
        ^^^^^^^^^^
    ...<4 lines>...
        _add_event=_add_event,
        ^^^^^^^^^^^^^^^^^^^^^^
    )
    ^
  File "C:\Users\Глеб\AppData\Local\Programs\Python\Python313\Lib\site-packages\sqlalchemy\orm\session.py", line 2239, in _execute_internal
    bind = self.get_bind(**bind_arguments)
  File "C:\Users\Глеб\AppData\Local\Programs\Python\Python313\Lib\site-packages\sqlalchemy\orm\session.py", line 2845, in get_bind
    raise sa_exc.UnboundExecutionError(
    ...<2 lines>...
    )
sqlalchemy.exc.UnboundExecutionError: Could not locate a bind configured on mapper Mapper[User(users)], SQL expression or this Session.
2025-02-02 23:31:05,098 - telegram.ext.Application - INFO - Application is stopping. This might take a moment.
2025-02-02 23:31:05,099 - telegram.ext.Application - INFO - Application.stop() complete
2025-02-02 23:31:05,101 - root - INFO - Завершение работы бота...
2025-02-02 23:32:16,287 - root - INFO - Бот успешно запущен!
2025-02-02 23:32:17,825 - telegram.ext.Application - INFO - Application started
2025-02-02 23:33:42,443 - telegram.ext.Application - INFO - Application is stopping. This might take a moment.
2025-02-02 23:33:42,443 - telegram.ext.Application - INFO - Application.stop() complete
2025-02-02 23:33:42,445 - root - INFO - Завершение работы бота...
2025-02-02 23:34:48,549 - root - INFO - Бот успешно запущен!
2025-02-02 23:34:50,100 - telegram.ext.Application - INFO - Application started
2025-02-02 23:38:50,808 - root - INFO - Бот успешно запущен!
2025-02-02 23:38:52,401 - telegram.ext.Application - INFO - Application started
2025-02-02 23:39:56,069 - telegram.ext.Application - ERROR - No error handlers are registered, logging exception.
Traceback (most recent call last):
  File "C:\Users\Глеб\AppData\Local\Programs\Python\Python313\Lib\site-packages\telegram\ext\_application.py", line 1325, in process_update
    await coroutine
  File "C:\Users\Глеб\AppData\Local\Programs\Python\Python313\Lib\site-packages\telegram\ext\_handlers\basehandler.py", line 158, in handle_update
    return await self.callback(update, context)
           ^^^^^^^^^^^^^^^^^^^^^^^^^^^^^^^^^^^^
  File "C:\Users\Глеб\Desktop\kas\app\handlers.py", line 30, in start
    get_user_context(user_id)  # Создаем контекст пользователя
    ~~~~~~~~~~~~~~~~^^^^^^^^^
  File "C:\Users\Глеб\Desktop\kas\app\handlers.py", line 24, in get_user_context
    user_contexts[user_id] = UserContext(user_id, session)
                             ~~~~~~~~~~~^^^^^^^^^^^^^^^^^^
  File "C:\Users\Глеб\Desktop\kas\app\shared.py", line 44, in __init__
    self.bot_params = self.load_user_params()
                      ~~~~~~~~~~~~~~~~~~~~~^^
  File "C:\Users\Глеб\Desktop\kas\app\shared.py", line 52, in load_user_params
    user = self.db_session.query(User).filter_by(id=self.user_id).first()
  File "C:\Users\Глеб\AppData\Local\Programs\Python\Python313\Lib\site-packages\sqlalchemy\orm\query.py", line 2754, in first
    return self.limit(1)._iter().first()  # type: ignore
           ~~~~~~~~~~~~~~~~~~~^^
  File "C:\Users\Глеб\AppData\Local\Programs\Python\Python313\Lib\site-packages\sqlalchemy\orm\query.py", line 2853, in _iter
    result: Union[ScalarResult[_T], Result[_T]] = self.session.execute(
                                                  ~~~~~~~~~~~~~~~~~~~~^
        statement,
        ^^^^^^^^^^
        params,
        ^^^^^^^
        execution_options={"_sa_orm_load_options": self.load_options},
        ^^^^^^^^^^^^^^^^^^^^^^^^^^^^^^^^^^^^^^^^^^^^^^^^^^^^^^^^^^^^^^
    )
    ^
  File "C:\Users\Глеб\AppData\Local\Programs\Python\Python313\Lib\site-packages\sqlalchemy\orm\session.py", line 2365, in execute
    return self._execute_internal(
           ~~~~~~~~~~~~~~~~~~~~~~^
        statement,
        ^^^^^^^^^^
    ...<4 lines>...
        _add_event=_add_event,
        ^^^^^^^^^^^^^^^^^^^^^^
    )
    ^
  File "C:\Users\Глеб\AppData\Local\Programs\Python\Python313\Lib\site-packages\sqlalchemy\orm\session.py", line 2239, in _execute_internal
    bind = self.get_bind(**bind_arguments)
  File "C:\Users\Глеб\AppData\Local\Programs\Python\Python313\Lib\site-packages\sqlalchemy\orm\session.py", line 2845, in get_bind
    raise sa_exc.UnboundExecutionError(
    ...<2 lines>...
    )
sqlalchemy.exc.UnboundExecutionError: Could not locate a bind configured on mapper Mapper[User(users)], SQL expression or this Session.
2025-02-02 23:53:53,680 - root - INFO - Бот успешно запущен!
2025-02-02 23:53:55,066 - root - ERROR - Критическая ошибка при запуске бота: cannot import name 'Session' from 'app.shared' (C:\Users\Глеб\Desktop\kas\app\shared.py)
2025-02-02 23:53:55,085 - root - INFO - Завершение работы бота...
2025-02-03 12:30:39,168 - root - INFO - Бот успешно запущен!
2025-02-03 12:30:40,684 - root - ERROR - Критическая ошибка при запуске бота: cannot import name 'start' from 'app.settings_handlers' (C:\Users\Глеб\Desktop\kas\app\settings_handlers.py)
2025-02-03 12:30:41,132 - root - ERROR - Не удалось отправить уведомление администратору: Chat not found
2025-02-03 12:30:41,134 - root - INFO - Завершение работы бота...
2025-02-03 14:37:20,451 - root - INFO - Бот успешно запущен!
2025-02-03 14:37:22,335 - telegram.ext.Application - INFO - Application started
2025-02-03 14:39:41,453 - root - INFO - Бот успешно запущен!
2025-02-03 14:39:43,116 - telegram.ext.Application - INFO - Application started
2025-02-03 14:40:09,214 - root - INFO - Команда /start вызвана пользователем 810668767
2025-02-03 15:06:44,997 - root - INFO - Выполнена покупка Buy(1) для пользователя 810668767: {'id': 'C02__515069628729315328040', 'clientOrderId': None, 'timestamp': 1738584404886, 'datetime': '2025-02-03T12:06:44.886Z', 'lastTradeTimestamp': None, 'status': None, 'symbol': 'KAS/USDT', 'type': 'market', 'timeInForce': 'IOC', 'side': 'buy', 'price': 0.105462, 'triggerPrice': None, 'average': None, 'amount': 398.59, 'cost': None, 'filled': None, 'remaining': None, 'fee': None, 'trades': [], 'info': {'symbol': 'KASUSDT', 'orderId': 'C02__515069628729315328040', 'orderListId': '-1', 'price': '0.105462', 'origQty': '398.59', 'type': 'MARKET', 'side': 'BUY', 'transactTime': '1738584404886'}, 'fees': [], 'lastUpdateTimestamp': None, 'postOnly': None, 'reduceOnly': None, 'stopPrice': None, 'takeProfitPrice': None, 'stopLossPrice': None}
2025-02-03 15:06:45,491 - root - INFO - Создан ордер на продажу Sell(1) для пользователя 810668767: {'id': 'C02__515069630830657536040', 'clientOrderId': None, 'timestamp': 1738584405387, 'datetime': '2025-02-03T12:06:45.387Z', 'lastTradeTimestamp': None, 'status': None, 'symbol': 'KAS/USDT', 'type': 'limit', 'timeInForce': None, 'side': 'sell', 'price': 0.100653, 'triggerPrice': None, 'average': None, 'amount': 398.59, 'cost': None, 'filled': None, 'remaining': None, 'fee': None, 'trades': [], 'info': {'symbol': 'KASUSDT', 'orderId': 'C02__515069630830657536040', 'orderListId': '-1', 'price': '0.100653', 'origQty': '398.59', 'type': 'LIMIT', 'side': 'SELL', 'transactTime': '1738584405387'}, 'fees': [], 'lastUpdateTimestamp': None, 'postOnly': None, 'reduceOnly': None, 'stopPrice': None, 'takeProfitPrice': None, 'stopLossPrice': None}
2025-02-03 15:06:50,261 - root - INFO - Команда /stop вызвана пользователем 810668767
2025-02-03 15:18:21,260 - root - ERROR - Ошибка при автоматической торговле для пользователя 810668767: mexc {"msg":"Oversold","code":30005}
2025-02-03 15:18:21,569 - root - INFO - Автоматическая торговля остановлена для пользователя 810668767.
2025-02-03 15:26:31,069 - telegram.ext.Application - INFO - Application is stopping. This might take a moment.
2025-02-03 15:26:31,070 - telegram.ext.Application - INFO - Application.stop() complete
2025-02-03 15:26:31,076 - root - INFO - Завершение работы бота...
2025-02-03 17:10:13,765 - root - INFO - Бот успешно запущен!
2025-02-03 17:10:15,384 - root - ERROR - Критическая ошибка при запуске бота: cannot import name 'start' from 'app.handlers' (C:\Users\Глеб\Desktop\kas\app\handlers.py)
2025-02-03 17:10:15,740 - root - INFO - Завершение работы бота...
2025-02-03 17:18:15,442 - root - INFO - Бот успешно запущен!
2025-02-03 17:18:16,936 - root - ERROR - Критическая ошибка при запуске бота: cannot import name 'buy' from 'app.buy_handlers' (C:\Users\Глеб\Desktop\kas\app\buy_handlers.py)
2025-02-03 17:18:17,304 - root - INFO - Завершение работы бота...
2025-02-03 17:40:08,850 - root - INFO - Бот успешно запущен!
2025-02-03 17:40:13,390 - telegram.ext.Application - INFO - Application started
2025-02-03 17:40:14,030 - root - INFO - Команда /start вызвана пользователем 810668767
2025-02-03 17:40:44,926 - telegram.ext.Application - ERROR - No error handlers are registered, logging exception.
Traceback (most recent call last):
  File "C:\Users\Глеб\AppData\Local\Programs\Python\Python313\Lib\site-packages\httpx\_transports\default.py", line 101, in map_httpcore_exceptions
    yield
  File "C:\Users\Глеб\AppData\Local\Programs\Python\Python313\Lib\site-packages\httpx\_transports\default.py", line 394, in handle_async_request
    resp = await self._pool.handle_async_request(req)
           ^^^^^^^^^^^^^^^^^^^^^^^^^^^^^^^^^^^^^^^^^^
  File "C:\Users\Глеб\AppData\Local\Programs\Python\Python313\Lib\site-packages\httpcore\_async\connection_pool.py", line 256, in handle_async_request
    raise exc from None
  File "C:\Users\Глеб\AppData\Local\Programs\Python\Python313\Lib\site-packages\httpcore\_async\connection_pool.py", line 236, in handle_async_request
    response = await connection.handle_async_request(
               ^^^^^^^^^^^^^^^^^^^^^^^^^^^^^^^^^^^^^^
        pool_request.request
        ^^^^^^^^^^^^^^^^^^^^
    )
    ^
  File "C:\Users\Глеб\AppData\Local\Programs\Python\Python313\Lib\site-packages\httpcore\_async\connection.py", line 103, in handle_async_request
    return await self._connection.handle_async_request(request)
           ^^^^^^^^^^^^^^^^^^^^^^^^^^^^^^^^^^^^^^^^^^^^^^^^^^^^
  File "C:\Users\Глеб\AppData\Local\Programs\Python\Python313\Lib\site-packages\httpcore\_async\http11.py", line 136, in handle_async_request
    raise exc
  File "C:\Users\Глеб\AppData\Local\Programs\Python\Python313\Lib\site-packages\httpcore\_async\http11.py", line 106, in handle_async_request
    ) = await self._receive_response_headers(**kwargs)
        ^^^^^^^^^^^^^^^^^^^^^^^^^^^^^^^^^^^^^^^^^^^^^^
  File "C:\Users\Глеб\AppData\Local\Programs\Python\Python313\Lib\site-packages\httpcore\_async\http11.py", line 177, in _receive_response_headers
    event = await self._receive_event(timeout=timeout)
            ^^^^^^^^^^^^^^^^^^^^^^^^^^^^^^^^^^^^^^^^^^
  File "C:\Users\Глеб\AppData\Local\Programs\Python\Python313\Lib\site-packages\httpcore\_async\http11.py", line 217, in _receive_event
    data = await self._network_stream.read(
           ^^^^^^^^^^^^^^^^^^^^^^^^^^^^^^^^
        self.READ_NUM_BYTES, timeout=timeout
        ^^^^^^^^^^^^^^^^^^^^^^^^^^^^^^^^^^^^
    )
    ^
  File "C:\Users\Глеб\AppData\Local\Programs\Python\Python313\Lib\site-packages\httpcore\_backends\anyio.py", line 32, in read
    with map_exceptions(exc_map):
         ~~~~~~~~~~~~~~^^^^^^^^^
  File "C:\Users\Глеб\AppData\Local\Programs\Python\Python313\Lib\contextlib.py", line 162, in __exit__
    self.gen.throw(value)
    ~~~~~~~~~~~~~~^^^^^^^
  File "C:\Users\Глеб\AppData\Local\Programs\Python\Python313\Lib\site-packages\httpcore\_exceptions.py", line 14, in map_exceptions
    raise to_exc(exc) from exc
httpcore.ReadTimeout

The above exception was the direct cause of the following exception:

Traceback (most recent call last):
  File "C:\Users\Глеб\AppData\Local\Programs\Python\Python313\Lib\site-packages\telegram\request\_httpxrequest.py", line 293, in do_request
    res = await self._client.request(
          ^^^^^^^^^^^^^^^^^^^^^^^^^^^
    ...<6 lines>...
    )
    ^
  File "C:\Users\Глеб\AppData\Local\Programs\Python\Python313\Lib\site-packages\httpx\_client.py", line 1540, in request
    return await self.send(request, auth=auth, follow_redirects=follow_redirects)
           ^^^^^^^^^^^^^^^^^^^^^^^^^^^^^^^^^^^^^^^^^^^^^^^^^^^^^^^^^^^^^^^^^^^^^^
  File "C:\Users\Глеб\AppData\Local\Programs\Python\Python313\Lib\site-packages\httpx\_client.py", line 1629, in send
    response = await self._send_handling_auth(
               ^^^^^^^^^^^^^^^^^^^^^^^^^^^^^^^
    ...<4 lines>...
    )
    ^
  File "C:\Users\Глеб\AppData\Local\Programs\Python\Python313\Lib\site-packages\httpx\_client.py", line 1657, in _send_handling_auth
    response = await self._send_handling_redirects(
               ^^^^^^^^^^^^^^^^^^^^^^^^^^^^^^^^^^^^
    ...<3 lines>...
    )
    ^
  File "C:\Users\Глеб\AppData\Local\Programs\Python\Python313\Lib\site-packages\httpx\_client.py", line 1694, in _send_handling_redirects
    response = await self._send_single_request(request)
               ^^^^^^^^^^^^^^^^^^^^^^^^^^^^^^^^^^^^^^^^
  File "C:\Users\Глеб\AppData\Local\Programs\Python\Python313\Lib\site-packages\httpx\_client.py", line 1730, in _send_single_request
    response = await transport.handle_async_request(request)
               ^^^^^^^^^^^^^^^^^^^^^^^^^^^^^^^^^^^^^^^^^^^^^
  File "C:\Users\Глеб\AppData\Local\Programs\Python\Python313\Lib\site-packages\httpx\_transports\default.py", line 393, in handle_async_request
    with map_httpcore_exceptions():
         ~~~~~~~~~~~~~~~~~~~~~~~^^
  File "C:\Users\Глеб\AppData\Local\Programs\Python\Python313\Lib\contextlib.py", line 162, in __exit__
    self.gen.throw(value)
    ~~~~~~~~~~~~~~^^^^^^^
  File "C:\Users\Глеб\AppData\Local\Programs\Python\Python313\Lib\site-packages\httpx\_transports\default.py", line 118, in map_httpcore_exceptions
    raise mapped_exc(message) from exc
httpx.ReadTimeout

The above exception was the direct cause of the following exception:

Traceback (most recent call last):
  File "C:\Users\Глеб\AppData\Local\Programs\Python\Python313\Lib\site-packages\telegram\ext\_application.py", line 1325, in process_update
    await coroutine
  File "C:\Users\Глеб\AppData\Local\Programs\Python\Python313\Lib\site-packages\telegram\ext\_handlers\basehandler.py", line 158, in handle_update
    return await self.callback(update, context)
           ^^^^^^^^^^^^^^^^^^^^^^^^^^^^^^^^^^^^
  File "C:\Users\Глеб\Desktop\kas\app\settings_handlers.py", line 82, in set_api_keys
    await update.message.reply_text('Использование: /set_api_keys <api_key> <api_secret>')
  File "C:\Users\Глеб\AppData\Local\Programs\Python\Python313\Lib\site-packages\telegram\_message.py", line 1771, in reply_text
    return await self.get_bot().send_message(
           ^^^^^^^^^^^^^^^^^^^^^^^^^^^^^^^^^^
    ...<20 lines>...
    )
    ^
  File "C:\Users\Глеб\AppData\Local\Programs\Python\Python313\Lib\site-packages\telegram\ext\_extbot.py", line 2965, in send_message
    return await super().send_message(
           ^^^^^^^^^^^^^^^^^^^^^^^^^^^
    ...<21 lines>...
    )
    ^
  File "C:\Users\Глеб\AppData\Local\Programs\Python\Python313\Lib\site-packages\telegram\_bot.py", line 1019, in send_message
    return await self._send_message(
           ^^^^^^^^^^^^^^^^^^^^^^^^^
    ...<19 lines>...
    )
    ^
  File "C:\Users\Глеб\AppData\Local\Programs\Python\Python313\Lib\site-packages\telegram\ext\_extbot.py", line 610, in _send_message
    result = await super()._send_message(
             ^^^^^^^^^^^^^^^^^^^^^^^^^^^^
    ...<21 lines>...
    )
    ^
  File "C:\Users\Глеб\AppData\Local\Programs\Python\Python313\Lib\site-packages\telegram\_bot.py", line 731, in _send_message
    result = await self._post(
             ^^^^^^^^^^^^^^^^^
    ...<7 lines>...
    )
    ^
  File "C:\Users\Глеб\AppData\Local\Programs\Python\Python313\Lib\site-packages\telegram\_bot.py", line 619, in _post
    return await self._do_post(
           ^^^^^^^^^^^^^^^^^^^^
    ...<6 lines>...
    )
    ^
  File "C:\Users\Глеб\AppData\Local\Programs\Python\Python313\Lib\site-packages\telegram\ext\_extbot.py", line 354, in _do_post
    return await super()._do_post(
           ^^^^^^^^^^^^^^^^^^^^^^^
    ...<6 lines>...
    )
    ^
  File "C:\Users\Глеб\AppData\Local\Programs\Python\Python313\Lib\site-packages\telegram\_bot.py", line 648, in _do_post
    result = await request.post(
             ^^^^^^^^^^^^^^^^^^^
    ...<6 lines>...
    )
    ^
  File "C:\Users\Глеб\AppData\Local\Programs\Python\Python313\Lib\site-packages\telegram\request\_baserequest.py", line 202, in post
    result = await self._request_wrapper(
             ^^^^^^^^^^^^^^^^^^^^^^^^^^^^
    ...<7 lines>...
    )
    ^
  File "C:\Users\Глеб\AppData\Local\Programs\Python\Python313\Lib\site-packages\telegram\request\_baserequest.py", line 334, in _request_wrapper
    code, payload = await self.do_request(
                    ^^^^^^^^^^^^^^^^^^^^^^
    ...<7 lines>...
    )
    ^
  File "C:\Users\Глеб\AppData\Local\Programs\Python\Python313\Lib\site-packages\telegram\request\_httpxrequest.py", line 310, in do_request
    raise TimedOut from err
telegram.error.TimedOut: Timed out
2025-02-03 17:41:16,779 - root - ERROR - Ошибка при установке API-ключей для пользователя 810668767: Timed out
2025-02-03 17:48:44,762 - telegram.ext.Application - ERROR - No error handlers are registered, logging exception.
Traceback (most recent call last):
  File "C:\Users\Глеб\AppData\Local\Programs\Python\Python313\Lib\site-packages\httpx\_transports\default.py", line 101, in map_httpcore_exceptions
    yield
  File "C:\Users\Глеб\AppData\Local\Programs\Python\Python313\Lib\site-packages\httpx\_transports\default.py", line 394, in handle_async_request
    resp = await self._pool.handle_async_request(req)
           ^^^^^^^^^^^^^^^^^^^^^^^^^^^^^^^^^^^^^^^^^^
  File "C:\Users\Глеб\AppData\Local\Programs\Python\Python313\Lib\site-packages\httpcore\_async\connection_pool.py", line 256, in handle_async_request
    raise exc from None
  File "C:\Users\Глеб\AppData\Local\Programs\Python\Python313\Lib\site-packages\httpcore\_async\connection_pool.py", line 236, in handle_async_request
    response = await connection.handle_async_request(
               ^^^^^^^^^^^^^^^^^^^^^^^^^^^^^^^^^^^^^^
        pool_request.request
        ^^^^^^^^^^^^^^^^^^^^
    )
    ^
  File "C:\Users\Глеб\AppData\Local\Programs\Python\Python313\Lib\site-packages\httpcore\_async\connection.py", line 103, in handle_async_request
    return await self._connection.handle_async_request(request)
           ^^^^^^^^^^^^^^^^^^^^^^^^^^^^^^^^^^^^^^^^^^^^^^^^^^^^
  File "C:\Users\Глеб\AppData\Local\Programs\Python\Python313\Lib\site-packages\httpcore\_async\http11.py", line 136, in handle_async_request
    raise exc
  File "C:\Users\Глеб\AppData\Local\Programs\Python\Python313\Lib\site-packages\httpcore\_async\http11.py", line 106, in handle_async_request
    ) = await self._receive_response_headers(**kwargs)
        ^^^^^^^^^^^^^^^^^^^^^^^^^^^^^^^^^^^^^^^^^^^^^^
  File "C:\Users\Глеб\AppData\Local\Programs\Python\Python313\Lib\site-packages\httpcore\_async\http11.py", line 177, in _receive_response_headers
    event = await self._receive_event(timeout=timeout)
            ^^^^^^^^^^^^^^^^^^^^^^^^^^^^^^^^^^^^^^^^^^
  File "C:\Users\Глеб\AppData\Local\Programs\Python\Python313\Lib\site-packages\httpcore\_async\http11.py", line 231, in _receive_event
    raise RemoteProtocolError(msg)
httpcore.RemoteProtocolError: Server disconnected without sending a response.

The above exception was the direct cause of the following exception:

Traceback (most recent call last):
  File "C:\Users\Глеб\AppData\Local\Programs\Python\Python313\Lib\site-packages\telegram\request\_httpxrequest.py", line 293, in do_request
    res = await self._client.request(
          ^^^^^^^^^^^^^^^^^^^^^^^^^^^
    ...<6 lines>...
    )
    ^
  File "C:\Users\Глеб\AppData\Local\Programs\Python\Python313\Lib\site-packages\httpx\_client.py", line 1540, in request
    return await self.send(request, auth=auth, follow_redirects=follow_redirects)
           ^^^^^^^^^^^^^^^^^^^^^^^^^^^^^^^^^^^^^^^^^^^^^^^^^^^^^^^^^^^^^^^^^^^^^^
  File "C:\Users\Глеб\AppData\Local\Programs\Python\Python313\Lib\site-packages\httpx\_client.py", line 1629, in send
    response = await self._send_handling_auth(
               ^^^^^^^^^^^^^^^^^^^^^^^^^^^^^^^
    ...<4 lines>...
    )
    ^
  File "C:\Users\Глеб\AppData\Local\Programs\Python\Python313\Lib\site-packages\httpx\_client.py", line 1657, in _send_handling_auth
    response = await self._send_handling_redirects(
               ^^^^^^^^^^^^^^^^^^^^^^^^^^^^^^^^^^^^
    ...<3 lines>...
    )
    ^
  File "C:\Users\Глеб\AppData\Local\Programs\Python\Python313\Lib\site-packages\httpx\_client.py", line 1694, in _send_handling_redirects
    response = await self._send_single_request(request)
               ^^^^^^^^^^^^^^^^^^^^^^^^^^^^^^^^^^^^^^^^
  File "C:\Users\Глеб\AppData\Local\Programs\Python\Python313\Lib\site-packages\httpx\_client.py", line 1730, in _send_single_request
    response = await transport.handle_async_request(request)
               ^^^^^^^^^^^^^^^^^^^^^^^^^^^^^^^^^^^^^^^^^^^^^
  File "C:\Users\Глеб\AppData\Local\Programs\Python\Python313\Lib\site-packages\httpx\_transports\default.py", line 393, in handle_async_request
    with map_httpcore_exceptions():
         ~~~~~~~~~~~~~~~~~~~~~~~^^
  File "C:\Users\Глеб\AppData\Local\Programs\Python\Python313\Lib\contextlib.py", line 162, in __exit__
    self.gen.throw(value)
    ~~~~~~~~~~~~~~^^^^^^^
  File "C:\Users\Глеб\AppData\Local\Programs\Python\Python313\Lib\site-packages\httpx\_transports\default.py", line 118, in map_httpcore_exceptions
    raise mapped_exc(message) from exc
httpx.RemoteProtocolError: Server disconnected without sending a response.

The above exception was the direct cause of the following exception:

Traceback (most recent call last):
  File "C:\Users\Глеб\AppData\Local\Programs\Python\Python313\Lib\site-packages\telegram\ext\_updater.py", line 750, in _network_loop_retry
    if not await do_action():
           ^^^^^^^^^^^^^^^^^
  File "C:\Users\Глеб\AppData\Local\Programs\Python\Python313\Lib\site-packages\telegram\ext\_updater.py", line 744, in do_action
    return action_cb_task.result()
           ~~~~~~~~~~~~~~~~~~~~~^^
  File "C:\Users\Глеб\AppData\Local\Programs\Python\Python313\Lib\site-packages\telegram\ext\_updater.py", line 371, in polling_action_cb
    updates = await self.bot.get_updates(
              ^^^^^^^^^^^^^^^^^^^^^^^^^^^
    ...<7 lines>...
    )
    ^
  File "C:\Users\Глеб\AppData\Local\Programs\Python\Python313\Lib\site-packages\telegram\ext\_extbot.py", line 650, in get_updates
    updates = await super().get_updates(
              ^^^^^^^^^^^^^^^^^^^^^^^^^^
    ...<9 lines>...
    )
    ^
  File "C:\Users\Глеб\AppData\Local\Programs\Python\Python313\Lib\site-packages\telegram\_bot.py", line 4480, in get_updates
    await self._post(
    ^^^^^^^^^^^^^^^^^
    ...<7 lines>...
    ),
    ^
  File "C:\Users\Глеб\AppData\Local\Programs\Python\Python313\Lib\site-packages\telegram\_bot.py", line 619, in _post
    return await self._do_post(
           ^^^^^^^^^^^^^^^^^^^^
    ...<6 lines>...
    )
    ^
  File "C:\Users\Глеб\AppData\Local\Programs\Python\Python313\Lib\site-packages\telegram\ext\_extbot.py", line 354, in _do_post
    return await super()._do_post(
           ^^^^^^^^^^^^^^^^^^^^^^^
    ...<6 lines>...
    )
    ^
  File "C:\Users\Глеб\AppData\Local\Programs\Python\Python313\Lib\site-packages\telegram\_bot.py", line 648, in _do_post
    result = await request.post(
             ^^^^^^^^^^^^^^^^^^^
    ...<6 lines>...
    )
    ^
  File "C:\Users\Глеб\AppData\Local\Programs\Python\Python313\Lib\site-packages\telegram\request\_baserequest.py", line 202, in post
    result = await self._request_wrapper(
             ^^^^^^^^^^^^^^^^^^^^^^^^^^^^
    ...<7 lines>...
    )
    ^
  File "C:\Users\Глеб\AppData\Local\Programs\Python\Python313\Lib\site-packages\telegram\request\_baserequest.py", line 334, in _request_wrapper
    code, payload = await self.do_request(
                    ^^^^^^^^^^^^^^^^^^^^^^
    ...<7 lines>...
    )
    ^
  File "C:\Users\Глеб\AppData\Local\Programs\Python\Python313\Lib\site-packages\telegram\request\_httpxrequest.py", line 317, in do_request
    raise NetworkError(f"httpx.{err.__class__.__name__}: {err}") from err
telegram.error.NetworkError: httpx.RemoteProtocolError: Server disconnected without sending a response.
2025-02-03 17:51:59,039 - telegram.ext.Application - ERROR - No error handlers are registered, logging exception.
Traceback (most recent call last):
  File "C:\Users\Глеб\AppData\Local\Programs\Python\Python313\Lib\site-packages\httpx\_transports\default.py", line 101, in map_httpcore_exceptions
    yield
  File "C:\Users\Глеб\AppData\Local\Programs\Python\Python313\Lib\site-packages\httpx\_transports\default.py", line 394, in handle_async_request
    resp = await self._pool.handle_async_request(req)
           ^^^^^^^^^^^^^^^^^^^^^^^^^^^^^^^^^^^^^^^^^^
  File "C:\Users\Глеб\AppData\Local\Programs\Python\Python313\Lib\site-packages\httpcore\_async\connection_pool.py", line 256, in handle_async_request
    raise exc from None
  File "C:\Users\Глеб\AppData\Local\Programs\Python\Python313\Lib\site-packages\httpcore\_async\connection_pool.py", line 236, in handle_async_request
    response = await connection.handle_async_request(
               ^^^^^^^^^^^^^^^^^^^^^^^^^^^^^^^^^^^^^^
        pool_request.request
        ^^^^^^^^^^^^^^^^^^^^
    )
    ^
  File "C:\Users\Глеб\AppData\Local\Programs\Python\Python313\Lib\site-packages\httpcore\_async\connection.py", line 101, in handle_async_request
    raise exc
  File "C:\Users\Глеб\AppData\Local\Programs\Python\Python313\Lib\site-packages\httpcore\_async\connection.py", line 78, in handle_async_request
    stream = await self._connect(request)
             ^^^^^^^^^^^^^^^^^^^^^^^^^^^^
  File "C:\Users\Глеб\AppData\Local\Programs\Python\Python313\Lib\site-packages\httpcore\_async\connection.py", line 124, in _connect
    stream = await self._network_backend.connect_tcp(**kwargs)
             ^^^^^^^^^^^^^^^^^^^^^^^^^^^^^^^^^^^^^^^^^^^^^^^^^
  File "C:\Users\Глеб\AppData\Local\Programs\Python\Python313\Lib\site-packages\httpcore\_backends\auto.py", line 31, in connect_tcp
    return await self._backend.connect_tcp(
           ^^^^^^^^^^^^^^^^^^^^^^^^^^^^^^^^
    ...<5 lines>...
    )
    ^
  File "C:\Users\Глеб\AppData\Local\Programs\Python\Python313\Lib\site-packages\httpcore\_backends\anyio.py", line 113, in connect_tcp
    with map_exceptions(exc_map):
         ~~~~~~~~~~~~~~^^^^^^^^^
  File "C:\Users\Глеб\AppData\Local\Programs\Python\Python313\Lib\contextlib.py", line 162, in __exit__
    self.gen.throw(value)
    ~~~~~~~~~~~~~~^^^^^^^
  File "C:\Users\Глеб\AppData\Local\Programs\Python\Python313\Lib\site-packages\httpcore\_exceptions.py", line 14, in map_exceptions
    raise to_exc(exc) from exc
httpcore.ConnectError: [Errno 11001] getaddrinfo failed

The above exception was the direct cause of the following exception:

Traceback (most recent call last):
  File "C:\Users\Глеб\AppData\Local\Programs\Python\Python313\Lib\site-packages\telegram\request\_httpxrequest.py", line 293, in do_request
    res = await self._client.request(
          ^^^^^^^^^^^^^^^^^^^^^^^^^^^
    ...<6 lines>...
    )
    ^
  File "C:\Users\Глеб\AppData\Local\Programs\Python\Python313\Lib\site-packages\httpx\_client.py", line 1540, in request
    return await self.send(request, auth=auth, follow_redirects=follow_redirects)
           ^^^^^^^^^^^^^^^^^^^^^^^^^^^^^^^^^^^^^^^^^^^^^^^^^^^^^^^^^^^^^^^^^^^^^^
  File "C:\Users\Глеб\AppData\Local\Programs\Python\Python313\Lib\site-packages\httpx\_client.py", line 1629, in send
    response = await self._send_handling_auth(
               ^^^^^^^^^^^^^^^^^^^^^^^^^^^^^^^
    ...<4 lines>...
    )
    ^
  File "C:\Users\Глеб\AppData\Local\Programs\Python\Python313\Lib\site-packages\httpx\_client.py", line 1657, in _send_handling_auth
    response = await self._send_handling_redirects(
               ^^^^^^^^^^^^^^^^^^^^^^^^^^^^^^^^^^^^
    ...<3 lines>...
    )
    ^
  File "C:\Users\Глеб\AppData\Local\Programs\Python\Python313\Lib\site-packages\httpx\_client.py", line 1694, in _send_handling_redirects
    response = await self._send_single_request(request)
               ^^^^^^^^^^^^^^^^^^^^^^^^^^^^^^^^^^^^^^^^
  File "C:\Users\Глеб\AppData\Local\Programs\Python\Python313\Lib\site-packages\httpx\_client.py", line 1730, in _send_single_request
    response = await transport.handle_async_request(request)
               ^^^^^^^^^^^^^^^^^^^^^^^^^^^^^^^^^^^^^^^^^^^^^
  File "C:\Users\Глеб\AppData\Local\Programs\Python\Python313\Lib\site-packages\httpx\_transports\default.py", line 393, in handle_async_request
    with map_httpcore_exceptions():
         ~~~~~~~~~~~~~~~~~~~~~~~^^
  File "C:\Users\Глеб\AppData\Local\Programs\Python\Python313\Lib\contextlib.py", line 162, in __exit__
    self.gen.throw(value)
    ~~~~~~~~~~~~~~^^^^^^^
  File "C:\Users\Глеб\AppData\Local\Programs\Python\Python313\Lib\site-packages\httpx\_transports\default.py", line 118, in map_httpcore_exceptions
    raise mapped_exc(message) from exc
httpx.ConnectError: [Errno 11001] getaddrinfo failed

The above exception was the direct cause of the following exception:

Traceback (most recent call last):
  File "C:\Users\Глеб\AppData\Local\Programs\Python\Python313\Lib\site-packages\telegram\ext\_updater.py", line 750, in _network_loop_retry
    if not await do_action():
           ^^^^^^^^^^^^^^^^^
  File "C:\Users\Глеб\AppData\Local\Programs\Python\Python313\Lib\site-packages\telegram\ext\_updater.py", line 744, in do_action
    return action_cb_task.result()
           ~~~~~~~~~~~~~~~~~~~~~^^
  File "C:\Users\Глеб\AppData\Local\Programs\Python\Python313\Lib\site-packages\telegram\ext\_updater.py", line 371, in polling_action_cb
    updates = await self.bot.get_updates(
              ^^^^^^^^^^^^^^^^^^^^^^^^^^^
    ...<7 lines>...
    )
    ^
  File "C:\Users\Глеб\AppData\Local\Programs\Python\Python313\Lib\site-packages\telegram\ext\_extbot.py", line 650, in get_updates
    updates = await super().get_updates(
              ^^^^^^^^^^^^^^^^^^^^^^^^^^
    ...<9 lines>...
    )
    ^
  File "C:\Users\Глеб\AppData\Local\Programs\Python\Python313\Lib\site-packages\telegram\_bot.py", line 4480, in get_updates
    await self._post(
    ^^^^^^^^^^^^^^^^^
    ...<7 lines>...
    ),
    ^
  File "C:\Users\Глеб\AppData\Local\Programs\Python\Python313\Lib\site-packages\telegram\_bot.py", line 619, in _post
    return await self._do_post(
           ^^^^^^^^^^^^^^^^^^^^
    ...<6 lines>...
    )
    ^
  File "C:\Users\Глеб\AppData\Local\Programs\Python\Python313\Lib\site-packages\telegram\ext\_extbot.py", line 354, in _do_post
    return await super()._do_post(
           ^^^^^^^^^^^^^^^^^^^^^^^
    ...<6 lines>...
    )
    ^
  File "C:\Users\Глеб\AppData\Local\Programs\Python\Python313\Lib\site-packages\telegram\_bot.py", line 648, in _do_post
    result = await request.post(
             ^^^^^^^^^^^^^^^^^^^
    ...<6 lines>...
    )
    ^
  File "C:\Users\Глеб\AppData\Local\Programs\Python\Python313\Lib\site-packages\telegram\request\_baserequest.py", line 202, in post
    result = await self._request_wrapper(
             ^^^^^^^^^^^^^^^^^^^^^^^^^^^^
    ...<7 lines>...
    )
    ^
  File "C:\Users\Глеб\AppData\Local\Programs\Python\Python313\Lib\site-packages\telegram\request\_baserequest.py", line 334, in _request_wrapper
    code, payload = await self.do_request(
                    ^^^^^^^^^^^^^^^^^^^^^^
    ...<7 lines>...
    )
    ^
  File "C:\Users\Глеб\AppData\Local\Programs\Python\Python313\Lib\site-packages\telegram\request\_httpxrequest.py", line 317, in do_request
    raise NetworkError(f"httpx.{err.__class__.__name__}: {err}") from err
telegram.error.NetworkError: httpx.ConnectError: [Errno 11001] getaddrinfo failed
2025-02-03 19:10:59,873 - root - INFO - Бот успешно запущен!
2025-02-03 19:11:01,740 - telegram.ext.Application - INFO - Application started
2025-02-03 19:11:02,031 - telegram.ext.Application - ERROR - No error handlers are registered, logging exception.
Traceback (most recent call last):
  File "C:\Users\Глеб\AppData\Local\Programs\Python\Python313\Lib\site-packages\telegram\ext\_updater.py", line 750, in _network_loop_retry
    if not await do_action():
           ^^^^^^^^^^^^^^^^^
  File "C:\Users\Глеб\AppData\Local\Programs\Python\Python313\Lib\site-packages\telegram\ext\_updater.py", line 744, in do_action
    return action_cb_task.result()
           ~~~~~~~~~~~~~~~~~~~~~^^
  File "C:\Users\Глеб\AppData\Local\Programs\Python\Python313\Lib\site-packages\telegram\ext\_updater.py", line 371, in polling_action_cb
    updates = await self.bot.get_updates(
              ^^^^^^^^^^^^^^^^^^^^^^^^^^^
    ...<7 lines>...
    )
    ^
  File "C:\Users\Глеб\AppData\Local\Programs\Python\Python313\Lib\site-packages\telegram\ext\_extbot.py", line 650, in get_updates
    updates = await super().get_updates(
              ^^^^^^^^^^^^^^^^^^^^^^^^^^
    ...<9 lines>...
    )
    ^
  File "C:\Users\Глеб\AppData\Local\Programs\Python\Python313\Lib\site-packages\telegram\_bot.py", line 4480, in get_updates
    await self._post(
    ^^^^^^^^^^^^^^^^^
    ...<7 lines>...
    ),
    ^
  File "C:\Users\Глеб\AppData\Local\Programs\Python\Python313\Lib\site-packages\telegram\_bot.py", line 619, in _post
    return await self._do_post(
           ^^^^^^^^^^^^^^^^^^^^
    ...<6 lines>...
    )
    ^
  File "C:\Users\Глеб\AppData\Local\Programs\Python\Python313\Lib\site-packages\telegram\ext\_extbot.py", line 354, in _do_post
    return await super()._do_post(
           ^^^^^^^^^^^^^^^^^^^^^^^
    ...<6 lines>...
    )
    ^
  File "C:\Users\Глеб\AppData\Local\Programs\Python\Python313\Lib\site-packages\telegram\_bot.py", line 648, in _do_post
    result = await request.post(
             ^^^^^^^^^^^^^^^^^^^
    ...<6 lines>...
    )
    ^
  File "C:\Users\Глеб\AppData\Local\Programs\Python\Python313\Lib\site-packages\telegram\request\_baserequest.py", line 202, in post
    result = await self._request_wrapper(
             ^^^^^^^^^^^^^^^^^^^^^^^^^^^^
    ...<7 lines>...
    )
    ^
  File "C:\Users\Глеб\AppData\Local\Programs\Python\Python313\Lib\site-packages\telegram\request\_baserequest.py", line 385, in _request_wrapper
    raise Conflict(message)
telegram.error.Conflict: Conflict: terminated by other getUpdates request; make sure that only one bot instance is running
2025-02-03 19:11:06,144 - telegram.ext.Application - ERROR - No error handlers are registered, logging exception.
Traceback (most recent call last):
  File "C:\Users\Глеб\AppData\Local\Programs\Python\Python313\Lib\site-packages\telegram\ext\_updater.py", line 750, in _network_loop_retry
    if not await do_action():
           ^^^^^^^^^^^^^^^^^
  File "C:\Users\Глеб\AppData\Local\Programs\Python\Python313\Lib\site-packages\telegram\ext\_updater.py", line 744, in do_action
    return action_cb_task.result()
           ~~~~~~~~~~~~~~~~~~~~~^^
  File "C:\Users\Глеб\AppData\Local\Programs\Python\Python313\Lib\site-packages\telegram\ext\_updater.py", line 371, in polling_action_cb
    updates = await self.bot.get_updates(
              ^^^^^^^^^^^^^^^^^^^^^^^^^^^
    ...<7 lines>...
    )
    ^
  File "C:\Users\Глеб\AppData\Local\Programs\Python\Python313\Lib\site-packages\telegram\ext\_extbot.py", line 650, in get_updates
    updates = await super().get_updates(
              ^^^^^^^^^^^^^^^^^^^^^^^^^^
    ...<9 lines>...
    )
    ^
  File "C:\Users\Глеб\AppData\Local\Programs\Python\Python313\Lib\site-packages\telegram\_bot.py", line 4480, in get_updates
    await self._post(
    ^^^^^^^^^^^^^^^^^
    ...<7 lines>...
    ),
    ^
  File "C:\Users\Глеб\AppData\Local\Programs\Python\Python313\Lib\site-packages\telegram\_bot.py", line 619, in _post
    return await self._do_post(
           ^^^^^^^^^^^^^^^^^^^^
    ...<6 lines>...
    )
    ^
  File "C:\Users\Глеб\AppData\Local\Programs\Python\Python313\Lib\site-packages\telegram\ext\_extbot.py", line 354, in _do_post
    return await super()._do_post(
           ^^^^^^^^^^^^^^^^^^^^^^^
    ...<6 lines>...
    )
    ^
  File "C:\Users\Глеб\AppData\Local\Programs\Python\Python313\Lib\site-packages\telegram\_bot.py", line 648, in _do_post
    result = await request.post(
             ^^^^^^^^^^^^^^^^^^^
    ...<6 lines>...
    )
    ^
  File "C:\Users\Глеб\AppData\Local\Programs\Python\Python313\Lib\site-packages\telegram\request\_baserequest.py", line 202, in post
    result = await self._request_wrapper(
             ^^^^^^^^^^^^^^^^^^^^^^^^^^^^
    ...<7 lines>...
    )
    ^
  File "C:\Users\Глеб\AppData\Local\Programs\Python\Python313\Lib\site-packages\telegram\request\_baserequest.py", line 385, in _request_wrapper
    raise Conflict(message)
telegram.error.Conflict: Conflict: terminated by other getUpdates request; make sure that only one bot instance is running
2025-02-03 19:11:07,292 - telegram.ext.Application - ERROR - No error handlers are registered, logging exception.
Traceback (most recent call last):
  File "C:\Users\Глеб\AppData\Local\Programs\Python\Python313\Lib\site-packages\telegram\ext\_updater.py", line 750, in _network_loop_retry
    if not await do_action():
           ^^^^^^^^^^^^^^^^^
  File "C:\Users\Глеб\AppData\Local\Programs\Python\Python313\Lib\site-packages\telegram\ext\_updater.py", line 744, in do_action
    return action_cb_task.result()
           ~~~~~~~~~~~~~~~~~~~~~^^
  File "C:\Users\Глеб\AppData\Local\Programs\Python\Python313\Lib\site-packages\telegram\ext\_updater.py", line 371, in polling_action_cb
    updates = await self.bot.get_updates(
              ^^^^^^^^^^^^^^^^^^^^^^^^^^^
    ...<7 lines>...
    )
    ^
  File "C:\Users\Глеб\AppData\Local\Programs\Python\Python313\Lib\site-packages\telegram\ext\_extbot.py", line 650, in get_updates
    updates = await super().get_updates(
              ^^^^^^^^^^^^^^^^^^^^^^^^^^
    ...<9 lines>...
    )
    ^
  File "C:\Users\Глеб\AppData\Local\Programs\Python\Python313\Lib\site-packages\telegram\_bot.py", line 4480, in get_updates
    await self._post(
    ^^^^^^^^^^^^^^^^^
    ...<7 lines>...
    ),
    ^
  File "C:\Users\Глеб\AppData\Local\Programs\Python\Python313\Lib\site-packages\telegram\_bot.py", line 619, in _post
    return await self._do_post(
           ^^^^^^^^^^^^^^^^^^^^
    ...<6 lines>...
    )
    ^
  File "C:\Users\Глеб\AppData\Local\Programs\Python\Python313\Lib\site-packages\telegram\ext\_extbot.py", line 354, in _do_post
    return await super()._do_post(
           ^^^^^^^^^^^^^^^^^^^^^^^
    ...<6 lines>...
    )
    ^
  File "C:\Users\Глеб\AppData\Local\Programs\Python\Python313\Lib\site-packages\telegram\_bot.py", line 648, in _do_post
    result = await request.post(
             ^^^^^^^^^^^^^^^^^^^
    ...<6 lines>...
    )
    ^
  File "C:\Users\Глеб\AppData\Local\Programs\Python\Python313\Lib\site-packages\telegram\request\_baserequest.py", line 202, in post
    result = await self._request_wrapper(
             ^^^^^^^^^^^^^^^^^^^^^^^^^^^^
    ...<7 lines>...
    )
    ^
  File "C:\Users\Глеб\AppData\Local\Programs\Python\Python313\Lib\site-packages\telegram\request\_baserequest.py", line 385, in _request_wrapper
    raise Conflict(message)
telegram.error.Conflict: Conflict: terminated by other getUpdates request; make sure that only one bot instance is running
2025-02-03 19:11:11,888 - telegram.ext.Application - ERROR - No error handlers are registered, logging exception.
Traceback (most recent call last):
  File "C:\Users\Глеб\AppData\Local\Programs\Python\Python313\Lib\site-packages\telegram\ext\_updater.py", line 750, in _network_loop_retry
    if not await do_action():
           ^^^^^^^^^^^^^^^^^
  File "C:\Users\Глеб\AppData\Local\Programs\Python\Python313\Lib\site-packages\telegram\ext\_updater.py", line 744, in do_action
    return action_cb_task.result()
           ~~~~~~~~~~~~~~~~~~~~~^^
  File "C:\Users\Глеб\AppData\Local\Programs\Python\Python313\Lib\site-packages\telegram\ext\_updater.py", line 371, in polling_action_cb
    updates = await self.bot.get_updates(
              ^^^^^^^^^^^^^^^^^^^^^^^^^^^
    ...<7 lines>...
    )
    ^
  File "C:\Users\Глеб\AppData\Local\Programs\Python\Python313\Lib\site-packages\telegram\ext\_extbot.py", line 650, in get_updates
    updates = await super().get_updates(
              ^^^^^^^^^^^^^^^^^^^^^^^^^^
    ...<9 lines>...
    )
    ^
  File "C:\Users\Глеб\AppData\Local\Programs\Python\Python313\Lib\site-packages\telegram\_bot.py", line 4480, in get_updates
    await self._post(
    ^^^^^^^^^^^^^^^^^
    ...<7 lines>...
    ),
    ^
  File "C:\Users\Глеб\AppData\Local\Programs\Python\Python313\Lib\site-packages\telegram\_bot.py", line 619, in _post
    return await self._do_post(
           ^^^^^^^^^^^^^^^^^^^^
    ...<6 lines>...
    )
    ^
  File "C:\Users\Глеб\AppData\Local\Programs\Python\Python313\Lib\site-packages\telegram\ext\_extbot.py", line 354, in _do_post
    return await super()._do_post(
           ^^^^^^^^^^^^^^^^^^^^^^^
    ...<6 lines>...
    )
    ^
  File "C:\Users\Глеб\AppData\Local\Programs\Python\Python313\Lib\site-packages\telegram\_bot.py", line 648, in _do_post
    result = await request.post(
             ^^^^^^^^^^^^^^^^^^^
    ...<6 lines>...
    )
    ^
  File "C:\Users\Глеб\AppData\Local\Programs\Python\Python313\Lib\site-packages\telegram\request\_baserequest.py", line 202, in post
    result = await self._request_wrapper(
             ^^^^^^^^^^^^^^^^^^^^^^^^^^^^
    ...<7 lines>...
    )
    ^
  File "C:\Users\Глеб\AppData\Local\Programs\Python\Python313\Lib\site-packages\telegram\request\_baserequest.py", line 385, in _request_wrapper
    raise Conflict(message)
telegram.error.Conflict: Conflict: terminated by other getUpdates request; make sure that only one bot instance is running
2025-02-03 19:11:13,474 - telegram.ext.Application - ERROR - No error handlers are registered, logging exception.
Traceback (most recent call last):
  File "C:\Users\Глеб\AppData\Local\Programs\Python\Python313\Lib\site-packages\telegram\ext\_updater.py", line 750, in _network_loop_retry
    if not await do_action():
           ^^^^^^^^^^^^^^^^^
  File "C:\Users\Глеб\AppData\Local\Programs\Python\Python313\Lib\site-packages\telegram\ext\_updater.py", line 744, in do_action
    return action_cb_task.result()
           ~~~~~~~~~~~~~~~~~~~~~^^
  File "C:\Users\Глеб\AppData\Local\Programs\Python\Python313\Lib\site-packages\telegram\ext\_updater.py", line 371, in polling_action_cb
    updates = await self.bot.get_updates(
              ^^^^^^^^^^^^^^^^^^^^^^^^^^^
    ...<7 lines>...
    )
    ^
  File "C:\Users\Глеб\AppData\Local\Programs\Python\Python313\Lib\site-packages\telegram\ext\_extbot.py", line 650, in get_updates
    updates = await super().get_updates(
              ^^^^^^^^^^^^^^^^^^^^^^^^^^
    ...<9 lines>...
    )
    ^
  File "C:\Users\Глеб\AppData\Local\Programs\Python\Python313\Lib\site-packages\telegram\_bot.py", line 4480, in get_updates
    await self._post(
    ^^^^^^^^^^^^^^^^^
    ...<7 lines>...
    ),
    ^
  File "C:\Users\Глеб\AppData\Local\Programs\Python\Python313\Lib\site-packages\telegram\_bot.py", line 619, in _post
    return await self._do_post(
           ^^^^^^^^^^^^^^^^^^^^
    ...<6 lines>...
    )
    ^
  File "C:\Users\Глеб\AppData\Local\Programs\Python\Python313\Lib\site-packages\telegram\ext\_extbot.py", line 354, in _do_post
    return await super()._do_post(
           ^^^^^^^^^^^^^^^^^^^^^^^
    ...<6 lines>...
    )
    ^
  File "C:\Users\Глеб\AppData\Local\Programs\Python\Python313\Lib\site-packages\telegram\_bot.py", line 648, in _do_post
    result = await request.post(
             ^^^^^^^^^^^^^^^^^^^
    ...<6 lines>...
    )
    ^
  File "C:\Users\Глеб\AppData\Local\Programs\Python\Python313\Lib\site-packages\telegram\request\_baserequest.py", line 202, in post
    result = await self._request_wrapper(
             ^^^^^^^^^^^^^^^^^^^^^^^^^^^^
    ...<7 lines>...
    )
    ^
  File "C:\Users\Глеб\AppData\Local\Programs\Python\Python313\Lib\site-packages\telegram\request\_baserequest.py", line 385, in _request_wrapper
    raise Conflict(message)
telegram.error.Conflict: Conflict: terminated by other getUpdates request; make sure that only one bot instance is running
2025-02-03 19:11:18,820 - telegram.ext.Application - ERROR - No error handlers are registered, logging exception.
Traceback (most recent call last):
  File "C:\Users\Глеб\AppData\Local\Programs\Python\Python313\Lib\site-packages\telegram\ext\_updater.py", line 750, in _network_loop_retry
    if not await do_action():
           ^^^^^^^^^^^^^^^^^
  File "C:\Users\Глеб\AppData\Local\Programs\Python\Python313\Lib\site-packages\telegram\ext\_updater.py", line 744, in do_action
    return action_cb_task.result()
           ~~~~~~~~~~~~~~~~~~~~~^^
  File "C:\Users\Глеб\AppData\Local\Programs\Python\Python313\Lib\site-packages\telegram\ext\_updater.py", line 371, in polling_action_cb
    updates = await self.bot.get_updates(
              ^^^^^^^^^^^^^^^^^^^^^^^^^^^
    ...<7 lines>...
    )
    ^
  File "C:\Users\Глеб\AppData\Local\Programs\Python\Python313\Lib\site-packages\telegram\ext\_extbot.py", line 650, in get_updates
    updates = await super().get_updates(
              ^^^^^^^^^^^^^^^^^^^^^^^^^^
    ...<9 lines>...
    )
    ^
  File "C:\Users\Глеб\AppData\Local\Programs\Python\Python313\Lib\site-packages\telegram\_bot.py", line 4480, in get_updates
    await self._post(
    ^^^^^^^^^^^^^^^^^
    ...<7 lines>...
    ),
    ^
  File "C:\Users\Глеб\AppData\Local\Programs\Python\Python313\Lib\site-packages\telegram\_bot.py", line 619, in _post
    return await self._do_post(
           ^^^^^^^^^^^^^^^^^^^^
    ...<6 lines>...
    )
    ^
  File "C:\Users\Глеб\AppData\Local\Programs\Python\Python313\Lib\site-packages\telegram\ext\_extbot.py", line 354, in _do_post
    return await super()._do_post(
           ^^^^^^^^^^^^^^^^^^^^^^^
    ...<6 lines>...
    )
    ^
  File "C:\Users\Глеб\AppData\Local\Programs\Python\Python313\Lib\site-packages\telegram\_bot.py", line 648, in _do_post
    result = await request.post(
             ^^^^^^^^^^^^^^^^^^^
    ...<6 lines>...
    )
    ^
  File "C:\Users\Глеб\AppData\Local\Programs\Python\Python313\Lib\site-packages\telegram\request\_baserequest.py", line 202, in post
    result = await self._request_wrapper(
             ^^^^^^^^^^^^^^^^^^^^^^^^^^^^
    ...<7 lines>...
    )
    ^
  File "C:\Users\Глеб\AppData\Local\Programs\Python\Python313\Lib\site-packages\telegram\request\_baserequest.py", line 385, in _request_wrapper
    raise Conflict(message)
telegram.error.Conflict: Conflict: terminated by other getUpdates request; make sure that only one bot instance is running
2025-02-03 19:11:21,160 - telegram.ext.Application - ERROR - No error handlers are registered, logging exception.
Traceback (most recent call last):
  File "C:\Users\Глеб\AppData\Local\Programs\Python\Python313\Lib\site-packages\telegram\ext\_updater.py", line 750, in _network_loop_retry
    if not await do_action():
           ^^^^^^^^^^^^^^^^^
  File "C:\Users\Глеб\AppData\Local\Programs\Python\Python313\Lib\site-packages\telegram\ext\_updater.py", line 744, in do_action
    return action_cb_task.result()
           ~~~~~~~~~~~~~~~~~~~~~^^
  File "C:\Users\Глеб\AppData\Local\Programs\Python\Python313\Lib\site-packages\telegram\ext\_updater.py", line 371, in polling_action_cb
    updates = await self.bot.get_updates(
              ^^^^^^^^^^^^^^^^^^^^^^^^^^^
    ...<7 lines>...
    )
    ^
  File "C:\Users\Глеб\AppData\Local\Programs\Python\Python313\Lib\site-packages\telegram\ext\_extbot.py", line 650, in get_updates
    updates = await super().get_updates(
              ^^^^^^^^^^^^^^^^^^^^^^^^^^
    ...<9 lines>...
    )
    ^
  File "C:\Users\Глеб\AppData\Local\Programs\Python\Python313\Lib\site-packages\telegram\_bot.py", line 4480, in get_updates
    await self._post(
    ^^^^^^^^^^^^^^^^^
    ...<7 lines>...
    ),
    ^
  File "C:\Users\Глеб\AppData\Local\Programs\Python\Python313\Lib\site-packages\telegram\_bot.py", line 619, in _post
    return await self._do_post(
           ^^^^^^^^^^^^^^^^^^^^
    ...<6 lines>...
    )
    ^
  File "C:\Users\Глеб\AppData\Local\Programs\Python\Python313\Lib\site-packages\telegram\ext\_extbot.py", line 354, in _do_post
    return await super()._do_post(
           ^^^^^^^^^^^^^^^^^^^^^^^
    ...<6 lines>...
    )
    ^
  File "C:\Users\Глеб\AppData\Local\Programs\Python\Python313\Lib\site-packages\telegram\_bot.py", line 648, in _do_post
    result = await request.post(
             ^^^^^^^^^^^^^^^^^^^
    ...<6 lines>...
    )
    ^
  File "C:\Users\Глеб\AppData\Local\Programs\Python\Python313\Lib\site-packages\telegram\request\_baserequest.py", line 202, in post
    result = await self._request_wrapper(
             ^^^^^^^^^^^^^^^^^^^^^^^^^^^^
    ...<7 lines>...
    )
    ^
  File "C:\Users\Глеб\AppData\Local\Programs\Python\Python313\Lib\site-packages\telegram\request\_baserequest.py", line 385, in _request_wrapper
    raise Conflict(message)
telegram.error.Conflict: Conflict: terminated by other getUpdates request; make sure that only one bot instance is running
2025-02-03 19:11:24,640 - telegram.ext.Application - ERROR - No error handlers are registered, logging exception.
Traceback (most recent call last):
  File "C:\Users\Глеб\AppData\Local\Programs\Python\Python313\Lib\site-packages\telegram\ext\_updater.py", line 750, in _network_loop_retry
    if not await do_action():
           ^^^^^^^^^^^^^^^^^
  File "C:\Users\Глеб\AppData\Local\Programs\Python\Python313\Lib\site-packages\telegram\ext\_updater.py", line 744, in do_action
    return action_cb_task.result()
           ~~~~~~~~~~~~~~~~~~~~~^^
  File "C:\Users\Глеб\AppData\Local\Programs\Python\Python313\Lib\site-packages\telegram\ext\_updater.py", line 371, in polling_action_cb
    updates = await self.bot.get_updates(
              ^^^^^^^^^^^^^^^^^^^^^^^^^^^
    ...<7 lines>...
    )
    ^
  File "C:\Users\Глеб\AppData\Local\Programs\Python\Python313\Lib\site-packages\telegram\ext\_extbot.py", line 650, in get_updates
    updates = await super().get_updates(
              ^^^^^^^^^^^^^^^^^^^^^^^^^^
    ...<9 lines>...
    )
    ^
  File "C:\Users\Глеб\AppData\Local\Programs\Python\Python313\Lib\site-packages\telegram\_bot.py", line 4480, in get_updates
    await self._post(
    ^^^^^^^^^^^^^^^^^
    ...<7 lines>...
    ),
    ^
  File "C:\Users\Глеб\AppData\Local\Programs\Python\Python313\Lib\site-packages\telegram\_bot.py", line 619, in _post
    return await self._do_post(
           ^^^^^^^^^^^^^^^^^^^^
    ...<6 lines>...
    )
    ^
  File "C:\Users\Глеб\AppData\Local\Programs\Python\Python313\Lib\site-packages\telegram\ext\_extbot.py", line 354, in _do_post
    return await super()._do_post(
           ^^^^^^^^^^^^^^^^^^^^^^^
    ...<6 lines>...
    )
    ^
  File "C:\Users\Глеб\AppData\Local\Programs\Python\Python313\Lib\site-packages\telegram\_bot.py", line 648, in _do_post
    result = await request.post(
             ^^^^^^^^^^^^^^^^^^^
    ...<6 lines>...
    )
    ^
  File "C:\Users\Глеб\AppData\Local\Programs\Python\Python313\Lib\site-packages\telegram\request\_baserequest.py", line 202, in post
    result = await self._request_wrapper(
             ^^^^^^^^^^^^^^^^^^^^^^^^^^^^
    ...<7 lines>...
    )
    ^
  File "C:\Users\Глеб\AppData\Local\Programs\Python\Python313\Lib\site-packages\telegram\request\_baserequest.py", line 385, in _request_wrapper
    raise Conflict(message)
telegram.error.Conflict: Conflict: terminated by other getUpdates request; make sure that only one bot instance is running
2025-02-03 19:11:28,149 - telegram.ext.Application - ERROR - No error handlers are registered, logging exception.
Traceback (most recent call last):
  File "C:\Users\Глеб\AppData\Local\Programs\Python\Python313\Lib\site-packages\telegram\ext\_updater.py", line 750, in _network_loop_retry
    if not await do_action():
           ^^^^^^^^^^^^^^^^^
  File "C:\Users\Глеб\AppData\Local\Programs\Python\Python313\Lib\site-packages\telegram\ext\_updater.py", line 744, in do_action
    return action_cb_task.result()
           ~~~~~~~~~~~~~~~~~~~~~^^
  File "C:\Users\Глеб\AppData\Local\Programs\Python\Python313\Lib\site-packages\telegram\ext\_updater.py", line 371, in polling_action_cb
    updates = await self.bot.get_updates(
              ^^^^^^^^^^^^^^^^^^^^^^^^^^^
    ...<7 lines>...
    )
    ^
  File "C:\Users\Глеб\AppData\Local\Programs\Python\Python313\Lib\site-packages\telegram\ext\_extbot.py", line 650, in get_updates
    updates = await super().get_updates(
              ^^^^^^^^^^^^^^^^^^^^^^^^^^
    ...<9 lines>...
    )
    ^
  File "C:\Users\Глеб\AppData\Local\Programs\Python\Python313\Lib\site-packages\telegram\_bot.py", line 4480, in get_updates
    await self._post(
    ^^^^^^^^^^^^^^^^^
    ...<7 lines>...
    ),
    ^
  File "C:\Users\Глеб\AppData\Local\Programs\Python\Python313\Lib\site-packages\telegram\_bot.py", line 619, in _post
    return await self._do_post(
           ^^^^^^^^^^^^^^^^^^^^
    ...<6 lines>...
    )
    ^
  File "C:\Users\Глеб\AppData\Local\Programs\Python\Python313\Lib\site-packages\telegram\ext\_extbot.py", line 354, in _do_post
    return await super()._do_post(
           ^^^^^^^^^^^^^^^^^^^^^^^
    ...<6 lines>...
    )
    ^
  File "C:\Users\Глеб\AppData\Local\Programs\Python\Python313\Lib\site-packages\telegram\_bot.py", line 648, in _do_post
    result = await request.post(
             ^^^^^^^^^^^^^^^^^^^
    ...<6 lines>...
    )
    ^
  File "C:\Users\Глеб\AppData\Local\Programs\Python\Python313\Lib\site-packages\telegram\request\_baserequest.py", line 202, in post
    result = await self._request_wrapper(
             ^^^^^^^^^^^^^^^^^^^^^^^^^^^^
    ...<7 lines>...
    )
    ^
  File "C:\Users\Глеб\AppData\Local\Programs\Python\Python313\Lib\site-packages\telegram\request\_baserequest.py", line 385, in _request_wrapper
    raise Conflict(message)
telegram.error.Conflict: Conflict: terminated by other getUpdates request; make sure that only one bot instance is running
2025-02-03 19:11:33,499 - telegram.ext.Application - ERROR - No error handlers are registered, logging exception.
Traceback (most recent call last):
  File "C:\Users\Глеб\AppData\Local\Programs\Python\Python313\Lib\site-packages\telegram\ext\_updater.py", line 750, in _network_loop_retry
    if not await do_action():
           ^^^^^^^^^^^^^^^^^
  File "C:\Users\Глеб\AppData\Local\Programs\Python\Python313\Lib\site-packages\telegram\ext\_updater.py", line 744, in do_action
    return action_cb_task.result()
           ~~~~~~~~~~~~~~~~~~~~~^^
  File "C:\Users\Глеб\AppData\Local\Programs\Python\Python313\Lib\site-packages\telegram\ext\_updater.py", line 371, in polling_action_cb
    updates = await self.bot.get_updates(
              ^^^^^^^^^^^^^^^^^^^^^^^^^^^
    ...<7 lines>...
    )
    ^
  File "C:\Users\Глеб\AppData\Local\Programs\Python\Python313\Lib\site-packages\telegram\ext\_extbot.py", line 650, in get_updates
    updates = await super().get_updates(
              ^^^^^^^^^^^^^^^^^^^^^^^^^^
    ...<9 lines>...
    )
    ^
  File "C:\Users\Глеб\AppData\Local\Programs\Python\Python313\Lib\site-packages\telegram\_bot.py", line 4480, in get_updates
    await self._post(
    ^^^^^^^^^^^^^^^^^
    ...<7 lines>...
    ),
    ^
  File "C:\Users\Глеб\AppData\Local\Programs\Python\Python313\Lib\site-packages\telegram\_bot.py", line 619, in _post
    return await self._do_post(
           ^^^^^^^^^^^^^^^^^^^^
    ...<6 lines>...
    )
    ^
  File "C:\Users\Глеб\AppData\Local\Programs\Python\Python313\Lib\site-packages\telegram\ext\_extbot.py", line 354, in _do_post
    return await super()._do_post(
           ^^^^^^^^^^^^^^^^^^^^^^^
    ...<6 lines>...
    )
    ^
  File "C:\Users\Глеб\AppData\Local\Programs\Python\Python313\Lib\site-packages\telegram\_bot.py", line 648, in _do_post
    result = await request.post(
             ^^^^^^^^^^^^^^^^^^^
    ...<6 lines>...
    )
    ^
  File "C:\Users\Глеб\AppData\Local\Programs\Python\Python313\Lib\site-packages\telegram\request\_baserequest.py", line 202, in post
    result = await self._request_wrapper(
             ^^^^^^^^^^^^^^^^^^^^^^^^^^^^
    ...<7 lines>...
    )
    ^
  File "C:\Users\Глеб\AppData\Local\Programs\Python\Python313\Lib\site-packages\telegram\request\_baserequest.py", line 385, in _request_wrapper
    raise Conflict(message)
telegram.error.Conflict: Conflict: terminated by other getUpdates request; make sure that only one bot instance is running
2025-02-03 19:11:38,859 - telegram.ext.Application - ERROR - No error handlers are registered, logging exception.
Traceback (most recent call last):
  File "C:\Users\Глеб\AppData\Local\Programs\Python\Python313\Lib\site-packages\telegram\ext\_updater.py", line 750, in _network_loop_retry
    if not await do_action():
           ^^^^^^^^^^^^^^^^^
  File "C:\Users\Глеб\AppData\Local\Programs\Python\Python313\Lib\site-packages\telegram\ext\_updater.py", line 744, in do_action
    return action_cb_task.result()
           ~~~~~~~~~~~~~~~~~~~~~^^
  File "C:\Users\Глеб\AppData\Local\Programs\Python\Python313\Lib\site-packages\telegram\ext\_updater.py", line 371, in polling_action_cb
    updates = await self.bot.get_updates(
              ^^^^^^^^^^^^^^^^^^^^^^^^^^^
    ...<7 lines>...
    )
    ^
  File "C:\Users\Глеб\AppData\Local\Programs\Python\Python313\Lib\site-packages\telegram\ext\_extbot.py", line 650, in get_updates
    updates = await super().get_updates(
              ^^^^^^^^^^^^^^^^^^^^^^^^^^
    ...<9 lines>...
    )
    ^
  File "C:\Users\Глеб\AppData\Local\Programs\Python\Python313\Lib\site-packages\telegram\_bot.py", line 4480, in get_updates
    await self._post(
    ^^^^^^^^^^^^^^^^^
    ...<7 lines>...
    ),
    ^
  File "C:\Users\Глеб\AppData\Local\Programs\Python\Python313\Lib\site-packages\telegram\_bot.py", line 619, in _post
    return await self._do_post(
           ^^^^^^^^^^^^^^^^^^^^
    ...<6 lines>...
    )
    ^
  File "C:\Users\Глеб\AppData\Local\Programs\Python\Python313\Lib\site-packages\telegram\ext\_extbot.py", line 354, in _do_post
    return await super()._do_post(
           ^^^^^^^^^^^^^^^^^^^^^^^
    ...<6 lines>...
    )
    ^
  File "C:\Users\Глеб\AppData\Local\Programs\Python\Python313\Lib\site-packages\telegram\_bot.py", line 648, in _do_post
    result = await request.post(
             ^^^^^^^^^^^^^^^^^^^
    ...<6 lines>...
    )
    ^
  File "C:\Users\Глеб\AppData\Local\Programs\Python\Python313\Lib\site-packages\telegram\request\_baserequest.py", line 202, in post
    result = await self._request_wrapper(
             ^^^^^^^^^^^^^^^^^^^^^^^^^^^^
    ...<7 lines>...
    )
    ^
  File "C:\Users\Глеб\AppData\Local\Programs\Python\Python313\Lib\site-packages\telegram\request\_baserequest.py", line 385, in _request_wrapper
    raise Conflict(message)
telegram.error.Conflict: Conflict: terminated by other getUpdates request; make sure that only one bot instance is running
2025-02-03 19:11:46,746 - telegram.ext.Application - ERROR - No error handlers are registered, logging exception.
Traceback (most recent call last):
  File "C:\Users\Глеб\AppData\Local\Programs\Python\Python313\Lib\site-packages\telegram\ext\_updater.py", line 750, in _network_loop_retry
    if not await do_action():
           ^^^^^^^^^^^^^^^^^
  File "C:\Users\Глеб\AppData\Local\Programs\Python\Python313\Lib\site-packages\telegram\ext\_updater.py", line 744, in do_action
    return action_cb_task.result()
           ~~~~~~~~~~~~~~~~~~~~~^^
  File "C:\Users\Глеб\AppData\Local\Programs\Python\Python313\Lib\site-packages\telegram\ext\_updater.py", line 371, in polling_action_cb
    updates = await self.bot.get_updates(
              ^^^^^^^^^^^^^^^^^^^^^^^^^^^
    ...<7 lines>...
    )
    ^
  File "C:\Users\Глеб\AppData\Local\Programs\Python\Python313\Lib\site-packages\telegram\ext\_extbot.py", line 650, in get_updates
    updates = await super().get_updates(
              ^^^^^^^^^^^^^^^^^^^^^^^^^^
    ...<9 lines>...
    )
    ^
  File "C:\Users\Глеб\AppData\Local\Programs\Python\Python313\Lib\site-packages\telegram\_bot.py", line 4480, in get_updates
    await self._post(
    ^^^^^^^^^^^^^^^^^
    ...<7 lines>...
    ),
    ^
  File "C:\Users\Глеб\AppData\Local\Programs\Python\Python313\Lib\site-packages\telegram\_bot.py", line 619, in _post
    return await self._do_post(
           ^^^^^^^^^^^^^^^^^^^^
    ...<6 lines>...
    )
    ^
  File "C:\Users\Глеб\AppData\Local\Programs\Python\Python313\Lib\site-packages\telegram\ext\_extbot.py", line 354, in _do_post
    return await super()._do_post(
           ^^^^^^^^^^^^^^^^^^^^^^^
    ...<6 lines>...
    )
    ^
  File "C:\Users\Глеб\AppData\Local\Programs\Python\Python313\Lib\site-packages\telegram\_bot.py", line 648, in _do_post
    result = await request.post(
             ^^^^^^^^^^^^^^^^^^^
    ...<6 lines>...
    )
    ^
  File "C:\Users\Глеб\AppData\Local\Programs\Python\Python313\Lib\site-packages\telegram\request\_baserequest.py", line 202, in post
    result = await self._request_wrapper(
             ^^^^^^^^^^^^^^^^^^^^^^^^^^^^
    ...<7 lines>...
    )
    ^
  File "C:\Users\Глеб\AppData\Local\Programs\Python\Python313\Lib\site-packages\telegram\request\_baserequest.py", line 385, in _request_wrapper
    raise Conflict(message)
telegram.error.Conflict: Conflict: terminated by other getUpdates request; make sure that only one bot instance is running
2025-02-03 19:11:54,599 - telegram.ext.Application - ERROR - No error handlers are registered, logging exception.
Traceback (most recent call last):
  File "C:\Users\Глеб\AppData\Local\Programs\Python\Python313\Lib\site-packages\telegram\ext\_updater.py", line 750, in _network_loop_retry
    if not await do_action():
           ^^^^^^^^^^^^^^^^^
  File "C:\Users\Глеб\AppData\Local\Programs\Python\Python313\Lib\site-packages\telegram\ext\_updater.py", line 744, in do_action
    return action_cb_task.result()
           ~~~~~~~~~~~~~~~~~~~~~^^
  File "C:\Users\Глеб\AppData\Local\Programs\Python\Python313\Lib\site-packages\telegram\ext\_updater.py", line 371, in polling_action_cb
    updates = await self.bot.get_updates(
              ^^^^^^^^^^^^^^^^^^^^^^^^^^^
    ...<7 lines>...
    )
    ^
  File "C:\Users\Глеб\AppData\Local\Programs\Python\Python313\Lib\site-packages\telegram\ext\_extbot.py", line 650, in get_updates
    updates = await super().get_updates(
              ^^^^^^^^^^^^^^^^^^^^^^^^^^
    ...<9 lines>...
    )
    ^
  File "C:\Users\Глеб\AppData\Local\Programs\Python\Python313\Lib\site-packages\telegram\_bot.py", line 4480, in get_updates
    await self._post(
    ^^^^^^^^^^^^^^^^^
    ...<7 lines>...
    ),
    ^
  File "C:\Users\Глеб\AppData\Local\Programs\Python\Python313\Lib\site-packages\telegram\_bot.py", line 619, in _post
    return await self._do_post(
           ^^^^^^^^^^^^^^^^^^^^
    ...<6 lines>...
    )
    ^
  File "C:\Users\Глеб\AppData\Local\Programs\Python\Python313\Lib\site-packages\telegram\ext\_extbot.py", line 354, in _do_post
    return await super()._do_post(
           ^^^^^^^^^^^^^^^^^^^^^^^
    ...<6 lines>...
    )
    ^
  File "C:\Users\Глеб\AppData\Local\Programs\Python\Python313\Lib\site-packages\telegram\_bot.py", line 648, in _do_post
    result = await request.post(
             ^^^^^^^^^^^^^^^^^^^
    ...<6 lines>...
    )
    ^
  File "C:\Users\Глеб\AppData\Local\Programs\Python\Python313\Lib\site-packages\telegram\request\_baserequest.py", line 202, in post
    result = await self._request_wrapper(
             ^^^^^^^^^^^^^^^^^^^^^^^^^^^^
    ...<7 lines>...
    )
    ^
  File "C:\Users\Глеб\AppData\Local\Programs\Python\Python313\Lib\site-packages\telegram\request\_baserequest.py", line 385, in _request_wrapper
    raise Conflict(message)
telegram.error.Conflict: Conflict: terminated by other getUpdates request; make sure that only one bot instance is running
2025-02-03 19:12:06,253 - telegram.ext.Application - ERROR - No error handlers are registered, logging exception.
Traceback (most recent call last):
  File "C:\Users\Глеб\AppData\Local\Programs\Python\Python313\Lib\site-packages\telegram\ext\_updater.py", line 750, in _network_loop_retry
    if not await do_action():
           ^^^^^^^^^^^^^^^^^
  File "C:\Users\Глеб\AppData\Local\Programs\Python\Python313\Lib\site-packages\telegram\ext\_updater.py", line 744, in do_action
    return action_cb_task.result()
           ~~~~~~~~~~~~~~~~~~~~~^^
  File "C:\Users\Глеб\AppData\Local\Programs\Python\Python313\Lib\site-packages\telegram\ext\_updater.py", line 371, in polling_action_cb
    updates = await self.bot.get_updates(
              ^^^^^^^^^^^^^^^^^^^^^^^^^^^
    ...<7 lines>...
    )
    ^
  File "C:\Users\Глеб\AppData\Local\Programs\Python\Python313\Lib\site-packages\telegram\ext\_extbot.py", line 650, in get_updates
    updates = await super().get_updates(
              ^^^^^^^^^^^^^^^^^^^^^^^^^^
    ...<9 lines>...
    )
    ^
  File "C:\Users\Глеб\AppData\Local\Programs\Python\Python313\Lib\site-packages\telegram\_bot.py", line 4480, in get_updates
    await self._post(
    ^^^^^^^^^^^^^^^^^
    ...<7 lines>...
    ),
    ^
  File "C:\Users\Глеб\AppData\Local\Programs\Python\Python313\Lib\site-packages\telegram\_bot.py", line 619, in _post
    return await self._do_post(
           ^^^^^^^^^^^^^^^^^^^^
    ...<6 lines>...
    )
    ^
  File "C:\Users\Глеб\AppData\Local\Programs\Python\Python313\Lib\site-packages\telegram\ext\_extbot.py", line 354, in _do_post
    return await super()._do_post(
           ^^^^^^^^^^^^^^^^^^^^^^^
    ...<6 lines>...
    )
    ^
  File "C:\Users\Глеб\AppData\Local\Programs\Python\Python313\Lib\site-packages\telegram\_bot.py", line 648, in _do_post
    result = await request.post(
             ^^^^^^^^^^^^^^^^^^^
    ...<6 lines>...
    )
    ^
  File "C:\Users\Глеб\AppData\Local\Programs\Python\Python313\Lib\site-packages\telegram\request\_baserequest.py", line 202, in post
    result = await self._request_wrapper(
             ^^^^^^^^^^^^^^^^^^^^^^^^^^^^
    ...<7 lines>...
    )
    ^
  File "C:\Users\Глеб\AppData\Local\Programs\Python\Python313\Lib\site-packages\telegram\request\_baserequest.py", line 385, in _request_wrapper
    raise Conflict(message)
telegram.error.Conflict: Conflict: terminated by other getUpdates request; make sure that only one bot instance is running
2025-02-03 19:12:10,663 - telegram.ext.Application - ERROR - No error handlers are registered, logging exception.
Traceback (most recent call last):
  File "C:\Users\Глеб\AppData\Local\Programs\Python\Python313\Lib\site-packages\telegram\ext\_updater.py", line 750, in _network_loop_retry
    if not await do_action():
           ^^^^^^^^^^^^^^^^^
  File "C:\Users\Глеб\AppData\Local\Programs\Python\Python313\Lib\site-packages\telegram\ext\_updater.py", line 744, in do_action
    return action_cb_task.result()
           ~~~~~~~~~~~~~~~~~~~~~^^
  File "C:\Users\Глеб\AppData\Local\Programs\Python\Python313\Lib\site-packages\telegram\ext\_updater.py", line 371, in polling_action_cb
    updates = await self.bot.get_updates(
              ^^^^^^^^^^^^^^^^^^^^^^^^^^^
    ...<7 lines>...
    )
    ^
  File "C:\Users\Глеб\AppData\Local\Programs\Python\Python313\Lib\site-packages\telegram\ext\_extbot.py", line 650, in get_updates
    updates = await super().get_updates(
              ^^^^^^^^^^^^^^^^^^^^^^^^^^
    ...<9 lines>...
    )
    ^
  File "C:\Users\Глеб\AppData\Local\Programs\Python\Python313\Lib\site-packages\telegram\_bot.py", line 4480, in get_updates
    await self._post(
    ^^^^^^^^^^^^^^^^^
    ...<7 lines>...
    ),
    ^
  File "C:\Users\Глеб\AppData\Local\Programs\Python\Python313\Lib\site-packages\telegram\_bot.py", line 619, in _post
    return await self._do_post(
           ^^^^^^^^^^^^^^^^^^^^
    ...<6 lines>...
    )
    ^
  File "C:\Users\Глеб\AppData\Local\Programs\Python\Python313\Lib\site-packages\telegram\ext\_extbot.py", line 354, in _do_post
    return await super()._do_post(
           ^^^^^^^^^^^^^^^^^^^^^^^
    ...<6 lines>...
    )
    ^
  File "C:\Users\Глеб\AppData\Local\Programs\Python\Python313\Lib\site-packages\telegram\_bot.py", line 648, in _do_post
    result = await request.post(
             ^^^^^^^^^^^^^^^^^^^
    ...<6 lines>...
    )
    ^
  File "C:\Users\Глеб\AppData\Local\Programs\Python\Python313\Lib\site-packages\telegram\request\_baserequest.py", line 202, in post
    result = await self._request_wrapper(
             ^^^^^^^^^^^^^^^^^^^^^^^^^^^^
    ...<7 lines>...
    )
    ^
  File "C:\Users\Глеб\AppData\Local\Programs\Python\Python313\Lib\site-packages\telegram\request\_baserequest.py", line 385, in _request_wrapper
    raise Conflict(message)
telegram.error.Conflict: Conflict: terminated by other getUpdates request; make sure that only one bot instance is running
2025-02-03 19:12:28,008 - telegram.ext.Application - ERROR - No error handlers are registered, logging exception.
Traceback (most recent call last):
  File "C:\Users\Глеб\AppData\Local\Programs\Python\Python313\Lib\site-packages\telegram\ext\_updater.py", line 750, in _network_loop_retry
    if not await do_action():
           ^^^^^^^^^^^^^^^^^
  File "C:\Users\Глеб\AppData\Local\Programs\Python\Python313\Lib\site-packages\telegram\ext\_updater.py", line 744, in do_action
    return action_cb_task.result()
           ~~~~~~~~~~~~~~~~~~~~~^^
  File "C:\Users\Глеб\AppData\Local\Programs\Python\Python313\Lib\site-packages\telegram\ext\_updater.py", line 371, in polling_action_cb
    updates = await self.bot.get_updates(
              ^^^^^^^^^^^^^^^^^^^^^^^^^^^
    ...<7 lines>...
    )
    ^
  File "C:\Users\Глеб\AppData\Local\Programs\Python\Python313\Lib\site-packages\telegram\ext\_extbot.py", line 650, in get_updates
    updates = await super().get_updates(
              ^^^^^^^^^^^^^^^^^^^^^^^^^^
    ...<9 lines>...
    )
    ^
  File "C:\Users\Глеб\AppData\Local\Programs\Python\Python313\Lib\site-packages\telegram\_bot.py", line 4480, in get_updates
    await self._post(
    ^^^^^^^^^^^^^^^^^
    ...<7 lines>...
    ),
    ^
  File "C:\Users\Глеб\AppData\Local\Programs\Python\Python313\Lib\site-packages\telegram\_bot.py", line 619, in _post
    return await self._do_post(
           ^^^^^^^^^^^^^^^^^^^^
    ...<6 lines>...
    )
    ^
  File "C:\Users\Глеб\AppData\Local\Programs\Python\Python313\Lib\site-packages\telegram\ext\_extbot.py", line 354, in _do_post
    return await super()._do_post(
           ^^^^^^^^^^^^^^^^^^^^^^^
    ...<6 lines>...
    )
    ^
  File "C:\Users\Глеб\AppData\Local\Programs\Python\Python313\Lib\site-packages\telegram\_bot.py", line 648, in _do_post
    result = await request.post(
             ^^^^^^^^^^^^^^^^^^^
    ...<6 lines>...
    )
    ^
  File "C:\Users\Глеб\AppData\Local\Programs\Python\Python313\Lib\site-packages\telegram\request\_baserequest.py", line 202, in post
    result = await self._request_wrapper(
             ^^^^^^^^^^^^^^^^^^^^^^^^^^^^
    ...<7 lines>...
    )
    ^
  File "C:\Users\Глеб\AppData\Local\Programs\Python\Python313\Lib\site-packages\telegram\request\_baserequest.py", line 385, in _request_wrapper
    raise Conflict(message)
telegram.error.Conflict: Conflict: terminated by other getUpdates request; make sure that only one bot instance is running
2025-02-03 19:12:32,148 - telegram.ext.Application - ERROR - No error handlers are registered, logging exception.
Traceback (most recent call last):
  File "C:\Users\Глеб\AppData\Local\Programs\Python\Python313\Lib\site-packages\telegram\ext\_updater.py", line 750, in _network_loop_retry
    if not await do_action():
           ^^^^^^^^^^^^^^^^^
  File "C:\Users\Глеб\AppData\Local\Programs\Python\Python313\Lib\site-packages\telegram\ext\_updater.py", line 744, in do_action
    return action_cb_task.result()
           ~~~~~~~~~~~~~~~~~~~~~^^
  File "C:\Users\Глеб\AppData\Local\Programs\Python\Python313\Lib\site-packages\telegram\ext\_updater.py", line 371, in polling_action_cb
    updates = await self.bot.get_updates(
              ^^^^^^^^^^^^^^^^^^^^^^^^^^^
    ...<7 lines>...
    )
    ^
  File "C:\Users\Глеб\AppData\Local\Programs\Python\Python313\Lib\site-packages\telegram\ext\_extbot.py", line 650, in get_updates
    updates = await super().get_updates(
              ^^^^^^^^^^^^^^^^^^^^^^^^^^
    ...<9 lines>...
    )
    ^
  File "C:\Users\Глеб\AppData\Local\Programs\Python\Python313\Lib\site-packages\telegram\_bot.py", line 4480, in get_updates
    await self._post(
    ^^^^^^^^^^^^^^^^^
    ...<7 lines>...
    ),
    ^
  File "C:\Users\Глеб\AppData\Local\Programs\Python\Python313\Lib\site-packages\telegram\_bot.py", line 619, in _post
    return await self._do_post(
           ^^^^^^^^^^^^^^^^^^^^
    ...<6 lines>...
    )
    ^
  File "C:\Users\Глеб\AppData\Local\Programs\Python\Python313\Lib\site-packages\telegram\ext\_extbot.py", line 354, in _do_post
    return await super()._do_post(
           ^^^^^^^^^^^^^^^^^^^^^^^
    ...<6 lines>...
    )
    ^
  File "C:\Users\Глеб\AppData\Local\Programs\Python\Python313\Lib\site-packages\telegram\_bot.py", line 648, in _do_post
    result = await request.post(
             ^^^^^^^^^^^^^^^^^^^
    ...<6 lines>...
    )
    ^
  File "C:\Users\Глеб\AppData\Local\Programs\Python\Python313\Lib\site-packages\telegram\request\_baserequest.py", line 202, in post
    result = await self._request_wrapper(
             ^^^^^^^^^^^^^^^^^^^^^^^^^^^^
    ...<7 lines>...
    )
    ^
  File "C:\Users\Глеб\AppData\Local\Programs\Python\Python313\Lib\site-packages\telegram\request\_baserequest.py", line 385, in _request_wrapper
    raise Conflict(message)
telegram.error.Conflict: Conflict: terminated by other getUpdates request; make sure that only one bot instance is running
2025-02-06 21:23:23,852 - root - INFO - Бот успешно запущен!
2025-02-06 21:23:25,705 - telegram.ext.Application - INFO - Application started
2025-02-06 21:23:44,448 - root - INFO - Команда /start вызвана пользователем 810668767
2025-02-06 21:27:51,383 - root - INFO - Выполнена покупка для пользователя 810668767: {'id': 'C02__516252700996890624040', 'clientOrderId': None, 'timestamp': 1738866471295, 'datetime': '2025-02-06T18:27:51.295Z', 'lastTradeTimestamp': None, 'status': None, 'symbol': 'KAS/USDT', 'type': 'market', 'timeInForce': 'IOC', 'side': 'buy', 'price': 0.089216, 'triggerPrice': None, 'average': None, 'amount': 15.0, 'cost': None, 'filled': None, 'remaining': None, 'fee': None, 'trades': [], 'info': {'symbol': 'KASUSDT', 'orderId': 'C02__516252700996890624040', 'orderListId': '-1', 'price': '0.089216', 'origQty': '15', 'type': 'MARKET', 'side': 'BUY', 'transactTime': '1738866471295'}, 'fees': [], 'lastUpdateTimestamp': None, 'postOnly': None, 'reduceOnly': None, 'stopPrice': None, 'takeProfitPrice': None, 'stopLossPrice': None}
2025-02-06 21:33:19,359 - telegram.ext.Application - INFO - Application is stopping. This might take a moment.
2025-02-06 21:33:19,360 - telegram.ext.Application - INFO - Application.stop() complete
2025-02-06 21:33:19,361 - root - INFO - Завершение работы бота...
2025-02-06 21:34:34,754 - root - INFO - Бот успешно запущен!
2025-02-06 21:34:36,044 - root - ERROR - Критическая ошибка при запуске бота: cannot import name 'buy' from 'app.buy_handlers' (C:\Users\Глеб\Desktop\kas\app\buy_handlers.py)
2025-02-06 21:34:36,374 - root - INFO - Завершение работы бота...
2025-02-06 21:41:54,347 - root - INFO - Бот успешно запущен!
2025-02-06 21:41:55,941 - telegram.ext.Application - INFO - Application started
2025-02-06 21:41:56,196 - root - INFO - Команда /start вызвана пользователем 810668767
2025-02-06 22:41:46,030 - root - ERROR - Неизвестная ошибка: 'Session' object is not callable
2025-02-06 22:41:46,032 - root - INFO - Завершение работы бота...
2025-02-06 22:53:46,177 - root - INFO - Бот успешно запущен!
2025-02-06 22:53:47,726 - root - ERROR - Критическая ошибка при запуске бота: cannot import name 'get_user_context' from 'app.shared' (C:\Users\Глеб\Desktop\kas\app\shared.py)
2025-02-06 22:53:48,206 - root - INFO - Завершение работы бота...
2025-02-06 23:25:26,326 - root - INFO - Бот успешно запущен!
2025-02-06 23:25:27,747 - root - ERROR - Критическая ошибка при запуске бота: cannot import name 'get_user_context' from 'app.shared' (C:\Users\Глеб\Desktop\kas\app\shared.py)
2025-02-06 23:25:28,120 - root - INFO - Завершение работы бота...
2025-02-06 23:36:01,947 - root - INFO - Бот успешно запущен!
2025-02-06 23:36:03,172 - root - ERROR - Критическая ошибка при запуске бота: cannot import name 'db_session' from 'app.shared' (C:\Users\Глеб\Desktop\kas\app\shared.py)
2025-02-06 23:36:03,548 - root - INFO - Завершение работы бота...
2025-02-06 23:53:28,290 - root - INFO - Бот успешно запущен!
2025-02-06 23:53:29,789 - root - ERROR - Критическая ошибка при запуске бота: cannot import name 'db_session' from 'app.database' (C:\Users\Глеб\Desktop\kas\app\database.py)
2025-02-06 23:53:30,307 - root - INFO - Завершение работы бота...
2025-02-06 23:54:56,387 - root - INFO - Бот успешно запущен!
2025-02-06 23:54:57,621 - root - ERROR - Критическая ошибка при запуске бота: cannot import name 'db_session' from 'app.database' (C:\Users\Глеб\Desktop\kas\app\database.py)
2025-02-06 23:54:57,933 - root - INFO - Завершение работы бота...
2025-02-07 00:15:07,614 - root - INFO - Бот успешно запущен!
2025-02-07 00:15:08,919 - root - ERROR - Критическая ошибка при запуске бота: name 'UserContext' is not defined
2025-02-07 00:15:09,254 - root - INFO - Завершение работы бота...
2025-02-10 10:27:24,122 - root - INFO - Бот успешно запущен!
2025-02-10 10:27:26,051 - root - ERROR - Критическая ошибка при запуске бота: name 'UserContext' is not defined
2025-02-10 10:27:26,758 - root - INFO - Завершение работы бота...
